<?xml version="1.0"?>
<robot xmlns:xacro="http://www.ros.org/wiki/xacro" name="d01_action_wheel">
    <xacro:property name="base_x_origin_to_wheel_origin" value="1.01"/>
    <xacro:property name="base_y_origin_to_wheel_origin" value="0.85"/>
    <xacro:property name="base_z_origin_to_wheel_origin" value="-0.5"/>

    <xacro:property name="M_PI" value="3.1415926535897931"/>

    <xacro:macro name="action_wheel" params="parent name radius length flipY translateX translateY">

        <link name="${name}_action_wheel">
            <visual>
                <origin xyz="0.0 0.0 0.0" rpy="${flipY*M_PI/2} 0  0"/>
                <geometry>
                    <cylinder radius="0.6" length="0.2"/>
                </geometry>
            </visual>
            <inertial>
                <origin xyz="0.0 0.0 0.0" />
                <mass value="1"/>
                <inertia ixx="1" ixy="0.0" ixz="0.0" iyy="1" iyz="0.0" izz="1"/>
            </inertial>
            <collision>
                <origin xyz="0.0 0.0 0.0" rpy="${flipY*M_PI/2} 0  0"/>
                <geometry>
                    <cylinder radius="${radius}" length="${length}"/>
                </geometry>
            </collision>
        </link>
        <joint name="${name}_action_wheel_joint" type="continuous">
            <parent link="${parent}"/>
            <child link="${name}_action_wheel"/>
            <origin xyz="${translateX * base_x_origin_to_wheel_origin} ${translateY * base_y_origin_to_wheel_origin} ${base_z_origin_to_wheel_origin}" rpy="0.0 0.0 0.0"/>
            <axis xyz="0 1 0"/>
            <limit effort="100" velocity="100"/>
            <joint_properties damping="0.0" friction="0.0"/>
        </joint>
        <transmission name="${name}_action_wheel_joint_trans">
            <type>transmission_interface/SimpleTransmission</type>
            <joint name="${name}_action_wheel_joint" />
            <actuator name="${name}_action_wheel_joint_motor">
                <hardwareInterface>EffortJointInterface</hardwareInterface>
                <mechanicalReduction>1</mechanicalReduction>
            </actuator>
        </transmission>
        <gazebo reference="${name}_action_wheel">
            <mu1 value="1.0"/>
            <mu2 value="1.0"/>
            <kp value="10000000.0" />
            <kd value="1.0" />
            <fdir1 value="1 0 0"/>
            <material>Gazebo/Grey</material>
            <turnGravityOff>false</turnGravityOff>
        </gazebo>
    </xacro:macro>
</robot>

    